<?xml version="1.0" encoding="utf-8"?>
<!-- =================================================================================== -->
<!-- |    This document was autogenerated by xacro from scara_cpe.xacro                | -->
<!-- |    EDITING THIS FILE BY HAND IS NOT RECOMMENDED                                 | -->
<!-- =================================================================================== -->
<robot name="scara_cpe">
  <!-- ros_control plugin -->
  <gazebo>
    <plugin filename="libgazebo_ros_control.so" name="gazebo_ros_control">
      <robotNamespace>/scara_cpe</robotNamespace>
      <robotSimType>gazebo_ros_control/DefaultRobotHWSim</robotSimType>
    </plugin>
  </gazebo>
  <!-- Link3 -->
  <gazebo reference="base_link">
    <mu1>0.2</mu1>
    <mu2>0.2</mu2>
    <material>Gazebo/Black</material>
  </gazebo>
  <!-- Link1 -->
  <gazebo reference="link1">
    <material>Gazebo/Orange</material>
  </gazebo>
  <!-- Link2 -->
  <gazebo reference="link2">
    <mu1>0.2</mu1>
    <mu2>0.2</mu2>
    <material>Gazebo/Black</material>
  </gazebo>
  <!-- LINK -->
  <link name="world"/>
  <link name="camera_link">
    <inertial>
      <mass value="0.001"/>
      <origin xyz="0 0 0"/>
      <inertia ixx="0.0001" ixy="0.0" ixz="0.0" iyy="0.0001" iyz="0.0" izz="0.0001"/>
    </inertial>
  </link>
  <link name="base_link">
    <visual>
      <origin rpy="-1.57079632679 0 -1.57079632679" xyz="0 0.034 0"/>
      <geometry>
        <mesh filename="package://scara_cpe_description/urdf/scara_cpe-base_link.dae" scale="0.001 0.001 0.001"/>
      </geometry>
    </visual>
    <inertial>
      <origin rpy="0 0 0" xyz="0 0.025 0"/>
      <mass value="0.1"/>
      <inertia ixx="0.0001" ixy="1e-12" ixz="1e-12" iyy="0.0001" iyz="1e-12" izz="0.0001"/>
    </inertial>
  </link>
  <link name="link1">
    <visual>
      <origin rpy="-1.57079632679 0 -1.57079632679" xyz="0 -0.012 0"/>
      <geometry>
        <mesh filename="package://scara_cpe_description/urdf/scara_cpe-link_1.dae" scale="0.001 0.001 0.001"/>
      </geometry>
    </visual>
    <collision>
      <origin rpy="0 0 0" xyz="0 0.04 0"/>
      <geometry>
        <box size="0.02 0.04 0.05"/>
      </geometry>
    </collision>
    <inertial>
      <origin rpy="0 0 0" xyz="0 0.04 0"/>
      <mass value="0.1"/>
      <inertia ixx="0.00003" ixy="1e-12" ixz="1e-12" iyy="0.00003" iyz="1e-12" izz="0.00003"/>
    </inertial>
  </link>
  <link name="link2">
    <visual>
      <origin rpy="-1.57079632679 0 -1.42579632679" xyz="0.0133 -0.092 0"/>
      <!-- -1.42579632679  - pi/2 + 0.145 -->
      <geometry>
        <mesh filename="package://scara_cpe_description/urdf/scara_cpe-link_2.dae" scale="0.001 0.001 0.001"/>
      </geometry>
    </visual>
    <collision>
      <origin rpy="0 0 0" xyz="0 0.0235 0"/>
      <geometry>
        <box size="0.032 0.047 0.06"/>
      </geometry>
    </collision>
    <inertial>
      <origin rpy="0 0 0" xyz="0 0.02 0"/>
      <mass value="0.1"/>
      <inertia ixx="0.0001" ixy="1e-12" ixz="1e-12" iyy="0.0001" iyz="1e-12" izz="0.0001"/>
    </inertial>
  </link>
  <link name="end_link">
  </link>
  <!-- JOINT -->
  <joint name="base_fixed" type="fixed">
    <parent link="world"/>
    <child link="base_link"/>
    <origin rpy="0 0 0" xyz="0 0 .035"/>
  </joint>
  <joint name="camera_fixed" type="fixed">
    <parent link="world"/>
    <child link="camera_link"/>
    <origin rpy="-1.87079632679 0 0" xyz="0 -0.3 0.2"/>
  </joint>
  <joint name="shoulder_1_joint" type="revolute">
    <parent link="base_link"/>
    <child link="link1"/>
    <origin rpy="0 0 0" xyz="0 0.048 0"/>
    <limit effort="1.5" lower="-1.57079632679" upper="1.57079632679" velocity="1.0"/>
    <axis xyz="0 0 1"/>
  </joint>
  <joint name="shoulder_2_joint" type="revolute">
    <parent link="link1"/>
    <child link="link2"/>
    <origin rpy="0 0 0" xyz="0 0.08 0"/>
    <limit effort="1.5" lower="-2.8" upper="2.8" velocity="1.0"/>
    <axis xyz="0 0 -1"/>
  </joint>
  <joint name="end_joint" type="fixed">
    <parent link="link2"/>
    <child link="end_link"/>
    <origin rpy="0 0 0" xyz="0 0.047 -0.025"/>
  </joint>
  <transmission name="tran1">
    <type>SimpleTransmission</type>
    <joint name="shoulder_1_joint">
      <hardwareInterface>hardware_interface/EffortJointInterface</hardwareInterface>
    </joint>
    <actuator name="motor1">
      <hardwareInterface>hardware_interface/EffortJointInterface</hardwareInterface>
      <mechanicalReduction>1</mechanicalReduction>
    </actuator>
  </transmission>
  <transmission name="tran2">
    <type>SimpleTransmission</type>
    <joint name="shoulder_2_joint">
      <hardwareInterface>hardware_interface/EffortJointInterface</hardwareInterface>
    </joint>
    <actuator name="motor2">
      <hardwareInterface>hardware_interface/EffortJointInterface</hardwareInterface>
      <mechanicalReduction>1</mechanicalReduction>
    </actuator>
  </transmission>
</robot>
